Workbook
Name _NST01: #REF!
Name nst_annhu: 'NST-EST2024-HU'!$B$4:$H$60

Sheet About
A1: NoH Number of Households | B1: New York | C1: 46185 | H1: State | I1: Abbr.
B2: =VLOOKUP(B1,H2:I52,2) -> NY | H2: Alabama | I2: AL
A3: Source: | B3: 2022-2050 | H3: Alaska | I3: AK
B4: Energy Information Administration | H4: Arizona | I4: AZ
B5: 2023 | H5: Arkansas | I5: AR
B6: Annual Energy Outlook 2023 | H6: California | I6: CA
B7: https://www.eia.gov/outlooks/archive/aeo23/tables_ref.php | H7: Colorado | I7: CO
B8: Table 4 | H8: Connecticut | I8: CT
H9: Delaware | I9: DE
B10: 2021 | H10: Florida | I10: FL
B11: Energy Information Administration | H11: Georgia | I11: GA
B12: 2022 | H12: Hawaii | I12: HI
B13: Annual Energy Outlook 2022 | H13: Idaho | I13: ID
B14: https://www.eia.gov/outlooks/archive/aeo22/tables_ref.php | H14: Illinois | I14: IL
B15: Table 4 | H15: Indiana | I15: IN
H16: Iowa | I16: IA
B17: State household data | H17: Kansas | I17: KS
B18: Census | H18: Kentucky | I18: KY
B19: 2025 | H19: Louisiana | I19: LA
B20: National, State, and County Housing Unit Totals: 2020-2024 | H20: Maine | I20: ME
B21: https://www.census.gov/data/tables/time-series/demo/popest/2020s-total-housing-units.html | H21: Maryland | I21: MD
H22: Massachusetts | I22: MA
H23: Michigan | I23: MI
H24: Minnesota | I24: MN
H25: Mississippi | I25: MS
H26: Missouri | I26: MO
H27: Montana | I27: MT
H28: Nebraska | I28: NE
H29: Nevada | I29: NV
H30: New Hampshire | I30: NH
H31: New Jersey | I31: NJ
H32: New Mexico | I32: NM
H33: New York | I33: NY
... H52: Wyoming | I52: WY

Sheet AEO 2023 Table 4
B1: ref2023.d020623a | C1: 2022 | D1: 2023 | E1: 2024 | F1: 2025 | G1: 2026 | H1: 2027 | I1: 2028 | J1: 2029 | K1: 2030 | L1: 2031 | M1: 2032 | N1: 2033 | O1: 2034 | P1: 2035 | Q1: 2036 | R1: 2037 | S1: 2038 | T1: 2039 | U1: 2040 | V1: 2041 | W1: 2042 | X1: 2043 | Y1: 2044 | Z1: 2045 | AA1: 2046 | AB1: 2047 | AC1: 2048 | AD1: 2049 | AE1: 2050
C3: Report | D3: Annual Energy Outlook 2023
C4: Scenario | D4: ref2023 | G4: Reference
C5: Datekey | D5: d020623a
C6: Release Date | E6: March 2023
A10: RKI000 | B10: 4. Residential Sector Key Indicators and Consumption | AF10: Average
B11: (quadrillion Btu, unless otherwise noted) | AF11: Annual
AF12: Change
B13: Key Indicators and Consumption | C13: 2022 | D13: 2023 | E13: 2024 | F13: 2025 | G13: 2026 | H13: 2027 | I13: 2028 | J13: 2029 | K13: 2030 | L13: 2031 | M13: 2032 | N13: 2033 | O13: 2034 | P13: 2035 | Q13: 2036 | R13: 2037 | S13: 2038 | T13: 2039 | U13: 2040 | V13: 2041 | W13: 2042 | X13: 2043 | Y13: 2044 | Z13: 2045 | AA13: 2046 | AB13: 2047 | AC13: 2048 | AD13: 2049 | AE13: 2050 | AF13: 2022–2050
B15: Key Indicators
B16: Households (millions)
A17: RKI000:ba_Single-Family | B17: Single-Family | C17: 86.924255 | D17: 87.748611 | E17: 88.618675 | F17: 89.519981 | G17: 90.411308 | H17: 91.302132 | I17: 92.198265 | J17: 93.091507 | K17: 93.970619 | L17: 94.836555 | M17: 95.694557 | N17: 96.533203 | O17: 97.347885 | P17: 98.154381 | Q17: 98.959145 | R17: 99.75724 | S17: 100.55006 | T17: 101.33466 | U17: 102.12499 | V17: 102.91761 | W17: 103.69783 | X17: 104.47331 | Y17: 105.24597 | Z17: 106.01605 | AA17: 106.78051 | AB17: 107.53815 | AC17: 108.28622 | AD17: 109.02242 | AE17: 109.74868 | AF17: 0.008362
A18: RKI000:ba_Multifamily | B18: Multifamily | C18: 32.842152 | D18: 33.209229 | E18: 33.535469 | F18: 33.85815 | G18: 34.181629 | H18: 34.507633 | I18: 34.834255 | J18: 35.155056 | K18: 35.46513 | L18: 35.769081 | M18: 36.0718 | N18: 36.366608 | O18: 36.650593 | P18: 36.930111 | Q18: 37.212017 | R18: 37.496159 | S18: 37.783924 | T18: 38.073307 | U18: 38.36647 | V18: 38.656506 | W18: 38.941956 | X18: 39.223991 | Y18: 39.501945 | Z18: 39.776779 | AA18: 40.048443 | AB18: 40.322777 | AC18: 40.595905 | AD18: 40.869537 | AE18: 41.144089 | AF18: 0.008081
A19: RKI000:ba_MobileHomes | B19: Mobile Homes | C19: 6.648376 | D19: 6.654435 | E19: 6.657747 | F19: 6.660283 | G19: 6.66859 | H19: 6.680898 | I19: 6.695705 | J19: 6.709839 | K19: 6.717811 | L19: 6.722091 | M19: 6.727011 | N19: 6.734098 | O19: 6.740673 | P19: 6.744905 | Q19: 6.74995 | R19: 6.752422 | S19: 6.751948 | T19: 6.750166 | U19: 6.750861 | V19: 6.753187 | W19: 6.756266 | X19: 6.759341 | Y19: 6.761881 | Z19: 6.763837 | AA19: 6.764435 | AB19: 6.765501 | AC19: 6.766449 | AD19: 6.766767 | AE19: 6.767235 | AF19: 0.000633
A20: RKI000:ba_Total | B20: Total | C20: 126.41478 | D20: 127.61227 | E20: 128.81189 | F20: 130.03841 | G20: 131.26154 | H20: 132.49066 | I20: 133.72823 | J20: 134.95641 | K20: 136.15355 | L20: 137.32773 | M20: 138.49336 | N20: 139.63391 | O20: 140.73915 | P20: 141.82939 | Q20: 142.92111 | R20: 144.00583 | S20: 145.08594 | T20: 146.15813 | U20: 147.24231 | V20: 148.3273 | W20: 149.39606 | X20: 150.45664 | Y20: 151.50981 | Z20: 152.55667 | AA20: 153.59338 | AB20: 154.62643 | AC20: 155.64857 | AD20: 156.65874 | AE20: 157.66 | AF20: 0.00792
A22: RKI000:ca_AverageHouseS | B22: Average House Square Footage | C22: 1798.9158 | D22: 1803.5209 | E22: 1808.4264 | F22: 1813.3185 | G22: 1818.0804 | H22: 1822.7229 | I22: 1827.2777 | J22: 1831.8 | K22: 1836.3394 | L22: 1840.8495 | M22: 1845.2855 | N22: 1849.6774 | O22: 1854.0608 | P22: 1858.4113 | Q22: 1862.6759 | R22: 1866.8663 | S22: 1870.9755 | T22: 1875.0114 | U22: 1878.9578 | V22: 1882.8684 | W22: 1886.7397 | X22: 1890.5779 | Y22: 1894.3921 | Z22: 1898.1798 | AA22: 1901.9388 | AB22: 1905.6209 | AC22: 1909.2523 | AD22: 1912.8229 | AE22: 1916.3303 | AF22: 0.002261
B24: Energy Intensity
B25: (million Btu per household)
A26: RKI000:da_DeliveredEner | B26: Gross End-use Consumption 1/ | C26: 93.909477 | D26: 92.769119 | E26: 89.479935 | F26: 89.052956 | G26: 88.647408 | H26: 88.231392 | I26: 87.719673 | J26: 87.082458 | K26: 86.372932 | L26: 85.637901 | M26: 84.930008 | N26: 84.330368 | O26: 83.726021 | P26: 83.229088 | Q26: 82.803543 | R26: 82.42997 | S26: 82.039726 | T26: 81.693481 | U26: 81.360573 | V26: 81.06002 | W26: 80.817673 | X26: 80.633194 | Y26: 80.500008 | Z26: 80.389549 | AA26: 80.279945 | AB26: 80.223389 | AC26: 80.211197 | AD26: 80.229492 | AE26: 80.285049 | AF26: -0.005583
A27: RKI000:da_TotalEnergyCo | B27: Delivered Energy Consumption | C27: 93.023323 | D27: 91.801674 | E27: 88.420021 | F27: 87.901169 | G27: 87.405548 | H27: 86.898582 | I27: 86.294922 | J27: 85.563858 | K27: 84.758438 | L27: 83.924873 | M27: 83.114105 | N27: 82.411514 | O27: 81.703484 | P27: 81.117577 | Q27: 80.600105 | R27: 80.131668 | S27: 79.641068 | T27: 79.188065 | U27: 78.743118 | V27: 78.324791 | W27: 77.958664 | X27: 77.644554 | Y27: 77.377632 | Z27: 77.127983 | AA27: 76.87487 | AB27: 76.670601 | AC27: 76.504471 | AD27: 76.365883 | AE27: 76.260414 | AF27: -0.007071
B28: (thousand Btu per square foot)
A29: RKI000:ea_DeliveredEner | B29: Gross End-use Consumption 1/ | C29: 52.203377 | D29: 51.437782 | E29: 49.479443 | F29: 49.110489 | G29: 48.758793 | H29: 48.406364 | I29: 48.005661 | J29: 47.539284 | K29: 47.035389 | L29: 46.520859 | M29: 46.025402 | N29: 45.591934 | O29: 45.158184 | P29: 44.785076 | Q29: 44.454079 | R29: 44.15419 | S29: 43.848637 | T29: 43.569595 | U29: 43.300903 | V29: 43.051346 | W29: 42.83456 | X29: 42.650024 | Y29: 42.493847 | Z29: 42.350861 | AA29: 42.209534 | AB29: 42.098293 | AC29: 42.011837 | AD29: 41.942982 | AE29: 41.895203 | AF29: -0.007825
A30: RKI000:ea_TotalEnergyCo | B30: Delivered Energy Consumption | C30: 51.710773 | D30: 50.901363 | E30: 48.893349 | F30: 48.475307 | G30: 48.075733 | H30: 47.675148 | I30: 47.225948 | J30: 46.710258 | K30: 46.156193 | L30: 45.590298 | M30: 45.041325 | N30: 44.554535 | O30: 44.067314 | P30: 43.648884 | Q30: 43.271141 | R30: 42.923088 | S30: 42.566601 | T30: 42.233379 | U30: 41.907867 | V30: 41.598656 | W30: 41.319248 | X30: 41.069218 | Y30: 40.845627 | Z30: 40.632603 | AA30: 40.419212 | AB30: 40.233921 | AC30: 40.070381 | AD30: 39.923134 | AE30: 39.795025 | AF30: -0.009311
B32: Energy Consumption by Fuel
B33: Electricity 1/
A34: RKI000:fa_SpaceHeating | B34: Space Heating | C34: 0.74562 | D34: 0.744025 | E34: 0.657572 | F34: 0.656949 | G34: 0.655732 | H34: 0.653215 | I34: 0.649408 | J34: 0.644338 | K34: 0.637851 | L34: 0.630493 | M34: 0.623023 | N34: 0.615132 | O34: 0.606908 | P34: 0.599838 | Q34: 0.593122 | R34: 0.586547 | S34: 0.579423 | T34: 0.572275 | U34: 0.565611 | V34: 0.559325 | W34: 0.553414 | X34: 0.54783 | Y34: 0.542214 | Z34: 0.536676 | AA34: 0.531381 | AB34: 0.526393 | AC34: 0.521432 | AD34: 0.516688 | AE34: 0.512384 | AF34: -0.013309
A35: RKI000:fa_SpaceCooling | B35: Space Cooling | C35: 0.853587 | D35: 0.735192 | E35: 0.890909 | F35: 0.91105 | G35: 0.930181 | H35: 0.950142 | I35: 0.969709 | J35: 0.988224 | K35: 1.004471 | L35: 1.019774 | M35: 1.036202 | N35: 1.052583 | O35: 1.069291 | P35: 1.088333 | Q35: 1.109122 | R35: 1.130924 | S35: 1.152515 | T35: 1.174549 | U35: 1.196908 | V35: 1.219416 | W35: 1.242558 | X35: 1.266365 | Y35: 1.29112 | Z35: 1.3168 | AA35: 1.344624 | AB35: 1.373569 | AC35: 1.403082 | AD35: 1.432529 | AE35: 1.463148 | AF35: 0.019433
A36: RKI000:fa_WaterHeating | B36: Water Heating | C36: 0.599797 | D36: 0.598845 | E36: 0.598786 | F36: 0.599582 | G36: 0.599536 | H36: 0.599125 | I36: 0.59802 | J36: 0.596113 | K36: 0.593223 | L36: 0.589911 | M36: 0.586847 | N36: 0.586124 | O36: 0.586146 | P36: 0.588552 | Q36: 0.591464 | R36: 0.594365 | S36: 0.596931 | T36: 0.599321 | U36: 0.601795 | V36: 0.604464 | W36: 0.607404 | X36: 0.610584 | Y36: 0.613738 | Z36: 0.616835 | AA36: 0.620251 | AB36: 0.623921 | AC36: 0.627667 | AD36: 0.631618 | AE36: 0.63608 | AF36: 0.0021
A37: RKI000:fa_Refrigeration | B37: Refrigeration | C37: 0.295558 | D37: 0.293987 | E37: 0.292668 | F37: 0.29163 | G37: 0.290783 | H37: 0.290158 | I37: 0.289778 | J37: 0.289615 | K37: 0.289659 | L37: 0.289986 | M37: 0.29063 | N37: 0.29157 | O37: 0.292795 | P37: 0.294343 | Q37: 0.296242 | R37: 0.298447 | S37: 0.30096 | T37: 0.303745 | U37: 0.306848 | V37: 0.310249 | W37: 0.313888 | X37: 0.317482 | Y37: 0.321024 | Z37: 0.324507 | AA37: 0.327915 | AB37: 0.33125 | AC37: 0.334496 | AD37: 0.337645 | AE37: 0.340702 | AF37: 0.00509
A38: RKI000:fa_Cooking | B38: Cooking | C38: 0.055863 | D38: 0.056202 | E38: 0.056536 | F38: 0.056875 | G38: 0.057205 | H38: 0.05753 | I38: 0.057848 | J38: 0.058138 | K38: 0.058391 | L38: 0.058604 | M38: 0.058781 | N38: 0.058966 | O38: 0.05917 | P38: 0.059404 | Q38: 0.05968 | R38: 0.059996 | S38: 0.060304 | T38: 0.060601 | U38: 0.060895 | V38: 0.061182 | W38: 0.061454 | X38: 0.061714 | Y38: 0.061964 | Z38: 0.062203 | AA38: 0.062434 | AB38: 0.062659 | AC38: 0.06288 | AD38: 0.063098 | AE38: 0.063319 | AF38: 0.004485
A39: RKI000:fa_ClothesDryers | B39: Clothes Dryers | C39: 0.222467 | D39: 0.227024 | E39: 0.231891 | F39: 0.237295 | G39: 0.242448 | H39: 0.247266 | I39: 0.251793 | J39: 0.25596 | K39: 0.259671 | L39: 0.263071 | M39: 0.266436 | N39: 0.269392 | O39: 0.272342 | P39: 0.275723 | Q39: 0.279342 | R39: 0.282799 | S39: 0.285963 | T39: 0.289075 | U39: 0.292206 | V39: 0.295411 | W39: 0.298723 | X39: 0.30216 | Y39: 0.305635 | Z39: 0.309109 | AA39: 0.31273 | AB39: 0.31651 | AC39: 0.320307 | AD39: 0.324172 | AE39: 0.328278 | AF39: 0.013993
A40: RKI000:fa_Freezers | B40: Freezers | C40: 0.069007 | D40: 0.06885 | E40: 0.068687 | F40: 0.068516 | G40: 0.068318 | H40: 0.068105 | I40: 0.067922 | J40: 0.067761 | K40: 0.067615 | L40: 0.067486 | M40: 0.067377 | N40: 0.067287 | O40: 0.067216 | P40: 0.067169 | Q40: 0.067159 | R40: 0.067178 | S40: 0.067229 | T40: 0.067311 | U40: 0.067431 | V40: 0.067596 | W40: 0.067794 | X40: 0.068036 | Y40: 0.068326 | Z40: 0.068666 | AA40: 0.069053 | AB40: 0.069481 | AC40: 0.069904 | AD40: 0.070319 | AE40: 0.070729 | AF40: 0.000881
A41: RKI000:fa_Lighting | B41: Lighting | C41: 0.22927 | D41: 0.21316 | E41: 0.206794 | F41: 0.205129 | G41: 0.2052 | H41: 0.206404 | I41: 0.20833 | J41: 0.210226 | K41: 0.209704 | L41: 0.209164 | M41: 0.208855 | N41: 0.208568 | O41: 0.208536 | P41: 0.209016 | Q41: 0.209627 | R41: 0.210178 | S41: 0.210558 | T41: 0.210954 | U41: 0.207703 | V41: 0.205012 | W41: 0.202911 | X41: 0.201467 | Y41: 0.200848 | Z41: 0.20064 | AA41: 0.200592 | AB41: 0.20073 | AC41: 0.200991 | AD41: 0.201423 | AE41: 0.202056 | AF41: -0.004503
A42: RKI000:fa_ClothesWasher | B42: Clothes Washers 2/ | C42: 0.037489 | D42: 0.037813 | E42: 0.038144 | F42: 0.038486 | G42: 0.038827 | H42: 0.039168 | I42: 0.039519 | J42: 0.039875 | K42: 0.040246 | L42: 0.040617 | M42: 0.040992 | N42: 0.041365 | O42: 0.041733 | P42: 0.042099 | Q42: 0.042465 | R42: 0.042828 | S42: 0.043187 | T42: 0.043542 | U42: 0.043898 | V42: 0.044252 | W42: 0.044599 | X42: 0.044942 | Y42: 0.045282 | Z42: 0.045619 | AA42: 0.045952 | AB42: 0.046283 | AC42: 0.046611 | AD42: 0.046936 | AE42: 0.047258 | AF42: 0.008305
A43: RKI000:fa_Dishwashers | B43: Dishwashers 2/ | C43: 0.027618 | D43: 0.028064 | E43: 0.028506 | F43: 0.028945 | G43: 0.02937 | H43: 0.029782 | I43: 0.030233 | J43: 0.030722 | K43: 0.031242 | L43: 0.031797 | M43: 0.032392 | N43: 0.033027 | O43: 0.033702 | P43: 0.034373 | Q43: 0.035043 | R43: 0.03571 | S43: 0.036375 | T43: 0.037036 | U43: 0.037698 | V43: 0.038359 | W43: 0.039015 | X43: 0.039667 | Y43: 0.040316 | Z43: 0.040962 | AA43: 0.041605 | AB43: 0.042245 | AC43: 0.042882 | AD43: 0.043514 | AE43: 0.044143 | AF43: 0.01689
A44: RKI000:fa_ColorTelevisi | B44: Televisions and Related Equipment 3/ | C44: 0.185092 | D44: 0.181559 | E44: 0.178365 | F44: 0.175692 | G44: 0.172951 | H44: 0.170143 | I44: 0.167198 | J44: 0.164139 | K44: 0.160987 | L44: 0.157867 | M44: 0.154866 | N44: 0.151867 | O44: 0.148998 | P44: 0.146585 | Q44: 0.144473 | R44: 0.142566 | S44: 0.14076 | T44: 0.139189 | U44: 0.13791 | V44: 0.136911 | W44: 0.136207 | X44: 0.135755 | Y44: 0.135537 | Z44: 0.135552 | AA44: 0.135802 | AB44: 0.136265 | AC44: 0.13685 | AD44: 0.137593 | AE44: 0.138527 | AF44: -0.010296
A45: RKI000:fa_PersonalCompu | B45: Computers and Related Equipment 4/ | C45: 0.120106 | D45: 0.118562 | E45: 0.116931 | F45: 0.115363 | G45: 0.113493 | H45: 0.111328 | I45: 0.108857 | J45: 0.106117 | K45: 0.103168 | L45: 0.100088 | M45: 0.09698 | N45: 0.093786 | O45: 0.09061 | P45: 0.087647 | Q45: 0.084848 | R45: 0.082133 | S45: 0.079493 | T45: 0.077008 | U45: 0.074726 | V45: 0.072652 | W45: 0.070825 | X45: 0.069227 | Y45: 0.067875 | Z45: 0.066753 | AA45: 0.065956 | AB45: 0.065417 | AC45: 0.065087 | AD45: 0.064993 | AE45: 0.065107 | AF45: -0.021632
... A50: RKI000:fa_PurchasedElec | B50: Purchased Electricity | C50: 5.147618 | D50: 5.046671 | E50: 5.113911 | F50: 5.157499 | G50: 5.199634 | H50: 5.245647 | I50: 5.28379 | J50: 5.31335 | K50: 5.334268 | L50: 5.351949 | M50: 5.371014 | N50: 5.391346 | O50: 5.410297 | P50: 5.442602 | Q50: 5.480425 | R50: 5.521421 | S50: 5.559047 | T50: 5.597267 | U50: 5.6349 | V50: 5.674541 | W50: 5.718532 | X50: 5.765529 | Y50: 5.815574 | Z50: 5.868124 | AA50: 5.925225 | AB50: 5.986255 | AC50: 6.048272 | AD50: 6.112339 | AE50: 6.182475 | AF50: 0.006564
B52: Natural Gas
A53: RKI000:ga_SpaceHeating | B53: Space Heating | C53: 3.73693 | D53: 3.786134 | E53: 3.524206 | F53: 3.534772 | G53: 3.540792 | H53: 3.53828 | I53: 3.529304 | J53: 3.510945 | K53: 3.487897 | L53: 3.462235 | M53: 3.436536 | N53: 3.41919 | O53: 3.398954 | P53: 3.379413 | Q53: 3.362053 | R53: 3.346112 | S53: 3.329438 | T53: 3.314799 | U53: 3.301509 | V53: 3.288682 | W53: 3.276622 | X53: 3.266367 | Y53: 3.257648 | Z53: 3.247816 | AA53: 3.234627 | AB53: 3.222775 | AC53: 3.212637 | AD53: 3.202551 | AE53: 3.191122 | AF53: -0.005623
...

Sheet AEO 2022 Table 4
B1: ref2021.d113020a | C1: 2020 | D1: 2021 | E1: 2022 | F1: 2023 | G1: 2024 | H1: 2025 | I1: 2026 | J1: 2027 | K1: 2028 | L1: 2029 | M1: 2030 | N1: 2031 | O1: 2032 | P1: 2033 | Q1: 2034 | R1: 2035 | S1: 2036 | T1: 2037 | U1: 2038 | V1: 2039 | W1: 2040 | X1: 2041 | Y1: 2042 | Z1: 2043 | AA1: 2044 | AB1: 2045 | AC1: 2046 | AD1: 2047 | AE1: 2048 | AF1: 2049 | AG1: 2050
C3: Report | D3: Annual Energy Outlook 2021
C4: Scenario | D4: ref2021 | G4: Reference case
C5: Datekey | D5: d113020a
C6: Release Date | E6: January 2021
A10: RKI000 | B10: 4. Residential Sector Key Indicators and Consumption | AH10: Compound
B11: (quadrillion Btu, unless otherwise noted) | AH11: Growth
AH12: 2020-2050
B13: Key Indicators and Consumption | C13: 2020 | D13: 2021 | E13: 2022 | F13: 2023 | G13: 2024 | H13: 2025 | I13: 2026 | J13: 2027 | K13: 2028 | L13: 2029 | M13: 2030 | N13: 2031 | O13: 2032 | P13: 2033 | Q13: 2034 | R13: 2035 | S13: 2036 | T13: 2037 | U13: 2038 | V13: 2039 | W13: 2040 | X13: 2041 | Y13: 2042 | Z13: 2043 | AA13: 2044 | AB13: 2045 | AC13: 2046 | AD13: 2047 | AE13: 2048 | AF13: 2049 | AG13: 2050 | AH13: (percent)
B15: Key Indicators
B16: Households (millions)
A17: RKI000:ba_Single-Family | B17: Single-Family | C17: 84.750443 | D17: 85.593697 | E17: 86.438118 | F17: 87.263756 | G17: 88.078079 | H17: 88.908073 | I17: 89.73056 | J17: 90.531715 | K17: 91.318695 | L17: 92.095459 | M17: 92.86319 | N17: 93.620483 | O17: 94.374603 | P17: 95.112335 | Q17: 95.831551 | R17: 96.548988 | S17: 97.25177 | T17: 97.942635 | U17: 98.626312 | V17: 99.30011 | W17: 99.974014 | X17: 100.64284 | Y17: 101.30791 | Z17: 101.97792 | AA17: 102.65668 | AB17: 103.34093 | AC17: 104.02688 | AD17: 104.70899 | AE17: 105.38845 | AF17: 106.0673 | AG17: 106.7465 | AH17: 0.007721
A18: RKI000:ba_Multifamily | B18: Multifamily | C18: 31.968704 | D18: 32.227859 | E18: 32.481697 | F18: 32.722111 | G18: 32.964333 | H18: 33.21796 | I18: 33.469734 | J18: 33.709866 | K18: 33.941967 | L18: 34.169193 | M18: 34.396915 | N18: 34.621048 | O18: 34.840218 | P18: 35.051422 | Q18: 35.255718 | R18: 35.458874 | S18: 35.655647 | T18: 35.851791 | U18: 36.050476 | V18: 36.251507 | W18: 36.451229 | X18: 36.649303 | Y18: 36.850163 | Z18: 37.053848 | AA18: 37.255768 | AB18: 37.454777 | AC18: 37.649311 | AD18: 37.844074 | AE18: 38.040798 | AF18: 38.240433 | AG18: 38.443745 | AH18: 0.006167
A19: RKI000:ba_MobileHomes | B19: Mobile Homes | C19: 6.663464 | D19: 6.648386 | E19: 6.634101 | F19: 6.620814 | G19: 6.610516 | H19: 6.604194 | I19: 6.605052 | J19: 6.602856 | K19: 6.597648 | L19: 6.586789 | M19: 6.571608 | N19: 6.555332 | O19: 6.53966 | P19: 6.524387 | Q19: 6.51122 | R19: 6.502039 | S19: 6.493465 | T19: 6.483514 | U19: 6.472738 | V19: 6.462773 | W19: 6.455459 | X19: 6.449031 | Y19: 6.444581 | Z19: 6.44286 | AA19: 6.443233 | AB19: 6.444091 | AC19: 6.442573 | AD19: 6.438198 | AE19: 6.432255 | AF19: 6.425656 | AG19: 6.41708 | AH19: -0.001255
A20: RKI000:ba_Total | B20: Total | C20: 123.38261 | D20: 124.46994 | E20: 125.55392 | F20: 126.60668 | G20: 127.65293 | H20: 128.73022 | I20: 129.80534 | J20: 130.84444 | K20: 131.85831 | L20: 132.85144 | M20: 133.83171 | N20: 134.79686 | O20: 135.75447 | P20: 136.68814 | Q20: 137.59848 | R20: 138.5099 | S20: 139.40088 | T20: 140.27795 | U20: 141.14952 | V20: 142.01439 | W20: 142.88071 | X20: 143.74118 | Y20: 144.60265 | Z20: 145.47463 | AA20: 146.35568 | AB20: 147.23979 | AC20: 148.11876 | AD20: 148.99127 | AE20: 149.8615 | AF20: 150.7334 | AG20: 151.60733 | AH20: 0.00689
A22: RKI000:ca_AverageHouseS | B22: Average House Square Footage | C22: 1789.3104 | D22: 1795.3578 | E22: 1801.4011 | F22: 1807.4683 | G22: 1813.4492 | H22: 1819.314 | I22: 1825.1085 | J22: 1830.9334 | K22: 1836.7738 | L22: 1842.624 | M22: 1848.4427 | N22: 1854.2422 | O22: 1860.0408 | P22: 1865.8373 | Q22: 1871.6088 | R22: 1877.3394 | S22: 1883.0591 | T22: 1888.739 | U22: 1894.366 | V22: 1899.9277 | W22: 1905.464 | X22: 1910.9752 | Y22: 1916.4247 | Z22: 1921.8323 | AA22: 1927.2421 | AB22: 1932.6647 | AC22: 1938.1177 | AD22: 1943.5543 | AE22: 1948.9592 | AF22: 1954.3284 | AG22: 1959.6641 | AH22: 0.003036
B24: Energy Intensity
B25: (million Btu per household)
A26: RKI000:da_DeliveredEner | B26: Gross End-use Consumption 1/ | C26: 92.738022 | D26: 91.586784 | E26: 91.880096 | F26: 91.11187 | G26: 90.4701 | H26: 89.770355 | I26: 89.065895 | J26: 88.379463 | K26: 87.773743 | L26: 87.20845 | M26: 86.633553 | N26: 86.134857 | O26: 85.702553 | P26: 85.281403 | Q26: 84.91935 | R26: 84.596985 | S26: 84.326233 | T26: 84.093864 | U26: 83.883667 | V26: 83.681618 | W26: 83.477539 | X26: 83.281693 | Y26: 83.101692 | Z26: 82.956818 | AA26: 82.820435 | AB26: 82.683517 | AC26: 82.575638 | AD26: 82.460793 | AE26: 82.357018 | AF26: 82.265587 | AG26: 82.199287 | AH26: -0.004013
A27: RKI000:da_TotalEnergyCo | B27: Delivered Energy Consumption | C27: 92.104782 | D27: 90.868225 | E27: 91.091621 | F27: 90.256592 | G27: 89.550323 | H27: 88.786705 | I27: 88.017479 | J27: 87.266571 | K27: 86.596436 | L27: 85.966888 | M27: 85.326958 | N27: 84.76181 | O27: 84.262253 | P27: 83.772934 | Q27: 83.341469 | R27: 82.949066 | S27: 82.607262 | T27: 82.303116 | U27: 82.020409 | V27: 81.745148 | W27: 81.466759 | X27: 81.195541 | Y27: 80.938629 | Z27: 80.715416 | AA27: 80.499275 | AB27: 80.280556 | AC27: 80.088921 | AD27: 79.888603 | AE27: 79.697121 | AF27: 79.516228 | AG27: 79.358765 | AH27: -0.004953
B28: (thousand Btu per square foot)
A29: RKI000:ea_DeliveredEner | B29: Gross End-use Consumption 1/ | C29: 51.828918 | D29: 51.013107 | E29: 51.004799 | F29: 50.408558 | G29: 49.888409 | H29: 49.342972 | I29: 48.800327 | J29: 48.270168 | K29: 47.786911 | L29: 47.3284 | M29: 46.868401 | N29: 46.452862 | O29: 46.07563 | P29: 45.706776 | Q29: 45.372383 | R29: 45.062168 | S29: 44.781513 | T29: 44.523811 | U29: 44.280605 | V29: 44.044632 | W29: 43.809559 | X29: 43.58073 | Y29: 43.362877 | Z29: 43.165482 | AA29: 42.973553 | AB29: 42.782131 | AC29: 42.606102 | AD29: 42.42783 | AE29: 42.25692 | AF29: 42.094044 | AG29: 41.945602 | AH29: -0.007028
A30: RKI000:ea_TotalEnergyCo | B30: Delivered Energy Consumption | C30: 51.475014 | D30: 50.612877 | E30: 50.567093 | F30: 49.935368 | G30: 49.381214 | H30: 48.802299 | I30: 48.225887 | J30: 47.662338 | K30: 47.145943 | L30: 46.654602 | M30: 46.161537 | N30: 45.712376 | O30: 45.301292 | P30: 44.898304 | Q30: 44.529324 | R30: 44.184376 | S30: 43.868649 | T30: 43.575695 | U30: 43.297024 | V30: 43.025398 | W30: 42.754288 | X30: 42.489059 | Y30: 42.234184 | Z30: 41.999199 | AA30: 41.769157 | AB30: 41.538795 | AC30: 41.323044 | AD30: 41.104385 | AE30: 40.892143 | AF30: 40.687241 | AG30: 40.496109 | AH30: -0.007964
B32: Energy Consumption by Fuel
B33: Electricity 1/
A34: RKI000:fa_SpaceHeating | B34: Space Heating | C34: 0.648975 | D34: 0.698359 | E34: 0.705675 | F34: 0.700579 | G34: 0.697104 | H34: 0.693829 | I34: 0.689615 | J34: 0.684867 | K34: 0.680389 | L34: 0.675741 | M34: 0.671278 | N34: 0.667093 | O34: 0.663156 | P34: 0.658869 | Q34: 0.654543 | R34: 0.650647 | S34: 0.646979 | T34: 0.643454 | U34: 0.640012 | V34: 0.636487 | W34: 0.633042 | X34: 0.629411 | Y34: 0.62568 | Z34: 0.622594 | AA34: 0.61931 | AB34: 0.61588 | AC34: 0.612716 | AD34: 0.609319 | AE34: 0.605898 | AF34: 0.602859 | AG34: 0.60021 | AH34: -0.0026
A35: RKI000:fa_SpaceCooling | B35: Space Cooling | C35: 0.805393 | D35: 0.766594 | E35: 0.861182 | F35: 0.874083 | G35: 0.887777 | H35: 0.902099 | I35: 0.915943 | J35: 0.929715 | K35: 0.944123 | L35: 0.958867 | M35: 0.974193 | N35: 0.990744 | O35: 1.008481 | P35: 1.025846 | Q35: 1.043779 | R35: 1.062911 | S35: 1.0832 | T35: 1.105031 | U35: 1.127032 | V35: 1.149105 | W35: 1.171538 | X35: 1.19348 | Y35: 1.216245 | Z35: 1.239965 | AA35: 1.264531 | AB35: 1.288882 | AC35: 1.313945 | AD35: 1.338515 | AE35: 1.364224 | AF35: 1.390646 | AG35: 1.418784 | AH35: 0.019053
A36: RKI000:fa_WaterHeating | B36: Water Heating | C36: 0.607549 | D36: 0.610272 | E36: 0.612486 | F36: 0.613276 | G36: 0.614697 | H36: 0.615558 | I36: 0.615516 | J36: 0.615339 | K36: 0.615263 | L36: 0.615159 | M36: 0.615446 | N36: 0.616189 | O36: 0.617558 | P36: 0.61869 | Q36: 0.620048 | R36: 0.621836 | S36: 0.624211 | T36: 0.626908 | U36: 0.629862 | V36: 0.632567 | W36: 0.635049 | X36: 0.637403 | Y36: 0.639668 | Z36: 0.642614 | AA36: 0.645529 | AB36: 0.648506 | AC36: 0.651785 | AD36: 0.655048 | AE36: 0.658462 | AF36: 0.662375 | AG36: 0.666767 | AH36: 0.003105
A37: RKI000:fa_Refrigeration | B37: Refrigeration | C37: 0.297571 | D37: 0.295346 | E37: 0.293784 | F37: 0.292026 | G37: 0.290424 | H37: 0.289083 | I37: 0.287936 | J37: 0.286922 | K37: 0.286075 | L37: 0.285419 | M37: 0.285 | N37: 0.284881 | O37: 0.285089 | P37: 0.285596 | Q37: 0.286414 | R37: 0.287589 | S37: 0.289068 | T37: 0.290839 | U37: 0.292919 | V37: 0.295274 | W37: 0.297926 | X37: 0.300858 | Y37: 0.304065 | Z37: 0.307271 | AA37: 0.310466 | AB37: 0.313629 | AC37: 0.316735 | AD37: 0.319768 | AE37: 0.322732 | AF37: 0.325633 | AG37: 0.32847 | AH37: 0.003299
A38: RKI000:fa_Cooking | B38: Cooking | C38: 0.055007 | D38: 0.055161 | E38: 0.055458 | F38: 0.055738 | G38: 0.056009 | H38: 0.056286 | I38: 0.056556 | J38: 0.056803 | K38: 0.057032 | L38: 0.057229 | M38: 0.057396 | N38: 0.057526 | O38: 0.057621 | P38: 0.057725 | Q38: 0.057854 | R38: 0.058017 | S38: 0.058215 | T38: 0.05845 | U38: 0.058677 | V38: 0.058894 | W38: 0.059105 | X38: 0.059305 | Y38: 0.059498 | Z38: 0.059687 | AA38: 0.059871 | AB38: 0.06005 | AC38: 0.060221 | AD38: 0.060386 | AE38: 0.060551 | AF38: 0.060719 | AG38: 0.060893 | AH38: 0.003394
A39: RKI000:fa_ClothesDryers | B39: Clothes Dryers | C39: 0.216421 | D39: 0.220387 | E39: 0.223927 | F39: 0.227024 | G39: 0.230421 | H39: 0.233791 | I39: 0.236868 | J39: 0.239735 | K39: 0.24266 | L39: 0.245586 | M39: 0.248642 | N39: 0.251748 | O39: 0.254999 | P39: 0.258105 | Q39: 0.261348 | R39: 0.264724 | S39: 0.268346 | T39: 0.271985 | U39: 0.27562 | V39: 0.279211 | W39: 0.282735 | X39: 0.286192 | Y39: 0.289572 | Z39: 0.293211 | AA39: 0.296797 | AB39: 0.300345 | AC39: 0.303959 | AD39: 0.307505 | AE39: 0.311091 | AF39: 0.314901 | AG39: 0.318894 | AH39: 0.013005
A40: RKI000:fa_Freezers | B40: Freezers | C40: 0.069181 | D40: 0.068847 | E40: 0.068696 | F40: 0.068514 | G40: 0.068303 | H40: 0.06808 | I40: 0.067833 | J40: 0.067552 | K40: 0.067286 | L40: 0.067036 | M40: 0.066805 | N40: 0.066594 | O40: 0.066407 | P40: 0.066239 | Q40: 0.066095 | R40: 0.065983 | S40: 0.0659 | T40: 0.065845 | U40: 0.065824 | V40: 0.065833 | W40: 0.065878 | X40: 0.065963 | Y40: 0.066088 | Z40: 0.066264 | AA40: 0.066497 | AB40: 0.066784 | AC40: 0.067123 | AD40: 0.067501 | AE40: 0.067876 | AF40: 0.068251 | AG40: 0.068624 | AH40: -0.00027
A41: RKI000:fa_Lighting | B41: Lighting | C41: 0.211247 | D41: 0.204709 | E41: 0.202325 | F41: 0.201331 | G41: 0.201363 | H41: 0.199969 | I41: 0.198834 | J41: 0.198385 | K41: 0.198653 | L41: 0.199213 | M41: 0.197419 | N41: 0.196248 | O41: 0.195597 | P41: 0.195114 | Q41: 0.194978 | R41: 0.195143 | S41: 0.195525 | T41: 0.196 | U41: 0.196543 | V41: 0.197114 | W41: 0.1944 | X41: 0.192285 | Y41: 0.190588 | Z41: 0.189504 | AA41: 0.18876 | AB41: 0.188243 | AC41: 0.187897 | AD41: 0.187552 | AE41: 0.187251 | AF41: 0.187096 | AG41: 0.187254 | AH41: -0.004011
A42: RKI000:fa_ClothesWasher | B42: Clothes Washers 2/ | C42: 0.036779 | D42: 0.037026 | E42: 0.037373 | F42: 0.03771 | G42: 0.038044 | H42: 0.038387 | I42: 0.038727 | J42: 0.039055 | K42: 0.039377 | L42: 0.039694 | M42: 0.040025 | N42: 0.040352 | O42: 0.040679 | P42: 0.041 | Q42: 0.041315 | R42: 0.041632 | S42: 0.041942 | T42: 0.042249 | U42: 0.042553 | V42: 0.042854 | W42: 0.043155 | X42: 0.043454 | Y42: 0.043751 | Z42: 0.044052 | AA42: 0.044355 | AB42: 0.044659 | AC42: 0.044962 | AD42: 0.045263 | AE42: 0.045562 | AF42: 0.045862 | AG42: 0.046163 | AH42: 0.007603
A43: RKI000:fa_Dishwashers | B43: Dishwashers 2/ | C43: 0.026617 | D43: 0.026992 | E43: 0.02743 | F43: 0.027852 | G43: 0.028262 | H43: 0.028667 | I43: 0.029058 | J43: 0.029425 | K43: 0.029825 | L43: 0.030258 | M43: 0.030725 | N43: 0.031229 | O43: 0.031774 | P43: 0.032359 | Q43: 0.032987 | R43: 0.033613 | S43: 0.034234 | T43: 0.03485 | U43: 0.035463 | V43: 0.036073 | W43: 0.036682 | X43: 0.037289 | Y43: 0.037894 | Z43: 0.038501 | AA43: 0.039109 | AB43: 0.039717 | AC43: 0.040323 | AD43: 0.040927 | AE43: 0.041529 | AF43: 0.04213 | AG43: 0.042731 | AH43: 0.015905
A44: RKI000:fa_ColorTelevisi | B44: Televisions and Related Equipment 3/ | C44: 0.209133 | D44: 0.205207 | E44: 0.202543 | F44: 0.200232 | G44: 0.198892 | H44: 0.198295 | I44: 0.19823 | J44: 0.19879 | K44: 0.200061 | L44: 0.202003 | M44: 0.204636 | N44: 0.207823 | O44: 0.2116 | P44: 0.215644 | Q44: 0.220005 | R44: 0.224683 | S44: 0.22967 | T44: 0.234747 | U44: 0.239803 | V44: 0.244645 | W44: 0.249117 | X44: 0.253057 | Y44: 0.25642 | Z44: 0.259709 | AA44: 0.262872 | AB44: 0.265931 | AC44: 0.268959 | AD44: 0.271838 | AE44: 0.274645 | AF44: 0.277515 | AG44: 0.280476 | AH44: 0.009832
A45: RKI000:fa_PersonalCompu | B45: Computers and Related Equipment 4/ | C45: 0.086664 | D45: 0.083833 | E45: 0.081495 | F45: 0.079249 | G45: 0.077311 | H45: 0.07555 | I45: 0.073889 | J45: 0.072344 | K45: 0.07094 | L45: 0.069648 | M45: 0.068455 | N45: 0.067301 | O45: 0.066194 | P45: 0.065015 | Q45: 0.063786 | R45: 0.062497 | S45: 0.061143 | T45: 0.059822 | U45: 0.058526 | V45: 0.05722 | W45: 0.055892 | X45: 0.054535 | Y45: 0.053136 | Z45: 0.051763 | AA45: 0.050343 | AB45: 0.048862 | AC45: 0.047324 | AD45: 0.045688 | AE45: 0.043971 | AF45: 0.042151 | AG45: 0.040223 | AH45: -0.025262
... A50: RKI000:fa_PurchasedElec | B50: Purchased Electricity | C50: 5.052812 | D50: 5.085636 | E50: 5.091427 | F50: 5.101829 | G50: 5.115852 | H50: 5.13157 | I50: 5.153872 | J50: 5.175931 | K50: 5.201604 | L50: 5.229164 | M50: 5.258111 | N50: 5.290325 | O50: 5.326496 | P50: 5.361025 | Q50: 5.400707 | R50: 5.442327 | S50: 5.487264 | T50: 5.534616 | U50: 5.582767 | V50: 5.630761 | W50: 5.67496 | X50: 5.718818 | Y50: 5.76369 | Z50: 5.813079 | AA50: 5.862924 | AB50: 5.91239 | AC50: 5.963741 | AD50: 6.01394 | AE50: 6.065893 | AF50: 6.12035 | AG50: 6.178349 | AH50: 0.006726
B52: Natural Gas
A53: RKI000:ga_SpaceHeating | B53: Space Heating | C53: 3.527199 | D53: 3.405752 | E53: 3.53601 | F53: 3.523748 | G53: 3.517663 | H53: 3.505749 | I53: 3.487102 | J53: 3.467178 | K53: 3.44851 | L53: 3.429626 | M53: 3.408028 | N53: 3.390023 | O53: 3.374133 | P53: 3.358309 | Q53: 3.342819 | R53: 3.329606 | S53: 3.317669 | T53: 3.306064 | U53: 3.295281 | V53: 3.284991 | W53: 3.276392 | X53: 3.267857 | Y53: 3.259522 | Z53: 3.251126 | AA53: 3.243215 | AB53: 3.234619 | AC53: 3.226072 | AD53: 3.216632 | AE53: 3.206716 | AF53: 3.195817 | AG53: 3.184887 | AH53: -0.003397
...

Sheet NST-EST2024-HU
B1: table with row headers in column A and column headers in rows 3 through 4. (leading dots indicate sub-parts)
B2: Annual Estimates of Housing Units for the United States, Regions, States, and the District of Columbia: April 1, 2020 to July 1, 2024
B3: Geographic Area | C3: April 1, 2020 Estimates Base | D3: Housing Unit Estimate (as of July 1)
D4: 2020 | E4: 2021 | F4: 2022 | G4: 2023 | H4: 2024
B5: United States | C5: 140498736 | D5: 140811440 | E5: 142172055 | F5: 143799370 | G5: 145359015 | H5: 146770711
B6: Northeast Region | C6: 24716535 | D6: 24739713 | E6: 24848852 | F6: 24988514 | G6: 25107966 | H6: 25223673
B7: Midwest Region | C7: 30458967 | D7: 30498361 | E7: 30681056 | F7: 30887488 | G7: 31087368 | H7: 31250348
B8: South Region | C8: 54542609 | D8: 54709662 | E8: 55441906 | F8: 56321445 | G8: 57178079 | H8: 57964002
B9: West Region | C9: 30780625 | D9: 30863704 | E9: 31200241 | F9: 31601923 | G9: 31985602 | H9: 32332688
A10: Alabama | B10: .Alabama | C10: 2288337 | D10: 2292694 | E10: 2313291 | F10: 2338998 | G10: 2359765 | H10: 2381817
A11: Alaska | B11: .Alaska | C11: 326199 | D11: 326593 | E11: 327863 | F11: 329245 | G11: 329677 | H11: 330463
A12: Arizona | B12: .Arizona | C12: 3081997 | D12: 3092927 | E12: 3139761 | F12: 3189962 | G12: 3243011 | H12: 3299651
A13: Arkansas | B13: .Arkansas | C13: 1365266 | D13: 1368214 | E13: 1380505 | F13: 1395318 | G13: 1408912 | H13: 1421037
A14: California | B14: .California | C14: 14392141 | D14: 14417494 | E14: 14524995 | F14: 14642752 | G14: 14762262 | H14: 14877904
A15: Colorado | B15: .Colorado | C15: 2491404 | D15: 2500752 | E15: 2540442 | F15: 2591143 | G15: 2639267 | H15: 2676415
A16: Connecticut | B16: .Connecticut | C16: 1530193 | D16: 1531476 | E16: 1536314 | F16: 1540585 | G16: 1546931 | H16: 1554121
A17: Delaware | B17: .Delaware | C17: 448735 | D17: 450131 | E17: 457806 | F17: 465556 | G17: 471318 | H17: 476405
A18: District of Columbia | B18: .District of Columbia | C18: 350365 | D18: 351429 | E18: 357360 | F18: 360735 | G18: 367036 | H18: 368736
A19: Florida | B19: .Florida | C19: 9865359 | D19: 9900384 | E19: 10051531 | F19: 10252120 | G19: 10448447 | H19: 10629918
A20: Georgia | B20: .Georgia | C20: 4410948 | D20: 4423066 | E20: 4474261 | F20: 4537424 | G20: 4609378 | H20: 4668859
A21: Hawaii | B21: .Hawaii | C21: 561064 | D21: 562001 | E21: 564848 | F21: 567983 | G21: 571997 | H21: 572781
... A60: Wyoming | B60: .Wyoming | C60: 271888 | D60: 272280 | E60: 274335 | F60: 277050 | G60: 280075 | H60: 281823
A61: The Census Bureau has reviewed this data product to ensure appropriate access, use, and disclosure avoidance protection of the confidential source data used to produce this product (Data Management System (DMS) number: P-6000042 and P-7501659 Disclosure Review Board (DRB) approval number: CBDRB-FY25-0053) | B61: The Census Bureau has reviewed this data product to ensure appropriate access, use, and disclosure avoidance protection of the confidential source data used to produce this product (Data Management System (DMS) number: P-6000042 and P-7501659. Disclosure Review Board (DRB) approval number: CBDRB-FY25-0053).
A62: Note: The estimates are based on the 2020 Census and reflect changes to the April 1, 2020 population due to the Count Question Resolution program and geographic program revisions The geographic boundaries for the 2024 housing unit estimates are as of January 1, 2024 For population and housing unit estimates methodology statements, see https://wwwcensusgov/programs-surveys/popest/technical-documentation/methodologyhtml See Geographic Terms and Definitions at https://wwwcensusgov/programs-surveys/popest/guidance-geographies/terms-and-definitionshtml for a list of the states that are included in each region | B62: Note: The estimates are based on the 2020 Census and reflect changes to the April 1, 2020 population due to the Count Question Resolution program and geographic program revisions. The geographic boundaries for the 2024 housing unit estimates are as of January 1, 2024. For population and housing unit estimates methodology statements, see https://www.census.gov/programs-surveys/popest/technical-documentation/methodology.html. See Geographic Terms and Definitions at https://www.census.gov/programs-surveys/popest/guidance-geographies/terms-and-definitions.html for a list of the states that are included in each region.
A63: Suggested Citation: | B63: Suggested Citation:
A64: Annual Estimates of Housing Units for the United States, Regions, States, and the District of Columbia: April 1, 2020 to July 1, 2024 (NST-EST2024-HU) | B64: Annual Estimates of Housing Units for the United States, Regions, States, and the District of Columbia: April 1, 2020 to July 1, 2024 (NST-EST2024-HU)
A65: Source: US Census Bureau, Population Division | B65: Source: U.S. Census Bureau, Population Division
A66: Release Date: May 2025 | B66: Release Date: May 2025

Sheet Total Pop
A1: Total Population for the U.S., the 50 States, and the District of Columbia: Census 2020 and Projections 2030-2050
A2: Released on July 1, 2024 by the University of Virginia, Weldon Cooper Center for Public Service, https://www.coopercenter.org/national-population-projections
A3: FIPS | B3: Geography Name | C3: Total Population
C4: 2020 | D4: 2030 | E4: 2040 | F4: 2050 | I4: Number of Households Projected to 2050 | Q4: Number of People Projected to 2050
A5: 0 | B5: United States | C5: 331449281 | D5: 3.4969586e+08 | E5: 3.6229347e+08 | F5: 3.7176698e+08 | I5: 2020 | J5: 2025 | K5: 2030 | L5: 2035 | M5: 2040 | N5: 2045 | O5: 2050 | Q5: 2020 | R5: 2025 | S5: 2030 | T5: 2035 | U5: 2040 | V5: 2045 | W5: 2050
A6: 1 | B6: Alabama | C6: 5024279 | D6: 5213942 | E6: 5269412 | F6: 5263068.8 | G6: =B6 -> Alabama | H6: AL | I6: =SUMIFS('NST-EST2024-HU'!D:D,'NST-EST2024-HU'!A:A,G6) -> 2292694 | J6: =AVERAGE(I6,K6) -> 2335967.8 | K6: =I6*$D6/$C6 -> 2379241.6 | L6: =AVERAGE(K6,M6) -> 2391897.7 | M6: =K6*$E6/$D6 -> 2404553.8 | N6: =AVERAGE(M6,O6) -> 2403106.6 | O6: =M6*$F6/$E6 -> 2401659.3 | P6: AL | Q6: =C6 -> 5024279 | R6: =AVERAGE(Q6,S6) -> 5119110.5 | S6: =Q6*$D6/$C6 -> 5213942 | T6: =AVERAGE(S6,U6) -> 5241677 | U6: =S6*$E6/$D6 -> 5269412 | V6: =AVERAGE(U6,W6) -> 5266240.4 | W6: =U6*$F6/$E6 -> 5263068.8
A7: 2 | B7: Alaska | C7: 733391 | D7: 751138.61 | E7: 745730.94 | F7: 731686.72 | G7: =B7 -> Alaska | H7: AK | I7: =SUMIFS('NST-EST2024-HU'!D:D,'NST-EST2024-HU'!A:A,G7) -> 326593 | J7: =AVERAGE(I7,K7) -> 330544.68 | K7: =I7*D7/C7 -> 334496.35 | L7: =AVERAGE(K7,M7) -> 333292.28 | M7: =K7*E7/D7 -> 332088.21 | N7: =AVERAGE(M7,O7) -> 328961.13 | O7: =M7*F7/E7 -> 325834.05 | P7: AK | Q7: =C7 -> 733391 | R7: =AVERAGE(Q7,S7) -> 742264.81 | S7: =Q7*$D7/$C7 -> 751138.61 | T7: =AVERAGE(S7,U7) -> 748434.78 | U7: =S7*$E7/$D7 -> 745730.94 | V7: =AVERAGE(U7,W7) -> 738708.83 | W7: =U7*$F7/$E7 -> 731686.72
A8: 4 | B8: Arizona | C8: 7151502 | D8: 7766235.9 | E8: 8354030.3 | F8: 8881011.8 | G8: =B8 -> Arizona | H8: AZ | I8: =SUMIFS('NST-EST2024-HU'!D:D,'NST-EST2024-HU'!A:A,G8) -> 3092927 | J8: =AVERAGE(I8,K8) -> 3225859 | K8: =I8*D8/C8 -> 3358791 | L8: =AVERAGE(K8,M8) -> 3485897.5 | M8: =K8*E8/D8 -> 3613004.1 | N8: =AVERAGE(M8,O8) -> 3726960.2 | O8: =M8*F8/E8 -> 3840916.4 | P8: AZ | Q8: =C8 -> 7151502 | R8: =AVERAGE(Q8,S8) -> 7458868.9 | S8: =Q8*$D8/$C8 -> 7766235.9 | T8: =AVERAGE(S8,U8) -> 8060133.1 | U8: =S8*$E8/$D8 -> 8354030.3 | V8: =AVERAGE(U8,W8) -> 8617521 | W8: =U8*$F8/$E8 -> 8881011.8
A9: 5 | B9: Arkansas | C9: 3011524 | D9: 3084795.8 | E9: 3063116.9 | F9: 3005949.3 | G9: =B9 -> Arkansas | H9: AR | I9: =SUMIFS('NST-EST2024-HU'!D:D,'NST-EST2024-HU'!A:A,G9) -> 1368214 | J9: =AVERAGE(I9,K9) -> 1384858.7 | K9: =I9*D9/C9 -> 1401503.3 | L9: =AVERAGE(K9,M9) -> 1396578.7 | M9: =K9*E9/D9 -> 1391654 | N9: =AVERAGE(M9,O9) -> 1378667.6 | O9: =M9*F9/E9 -> 1365681.3 | P9: AR | Q9: =C9 -> 3011524 | R9: =AVERAGE(Q9,S9) -> 3048159.9 | S9: =Q9*$D9/$C9 -> 3084795.8 | T9: =AVERAGE(S9,U9) -> 3073956.4 | U9: =S9*$E9/$D9 -> 3063116.9 | V9: =AVERAGE(U9,W9) -> 3034533.1 | W9: =U9*$F9/$E9 -> 3005949.3
A10: 6 | B10: California | C10: 39538223 | D10: 41321454 | E10: 42164453 | F10: 42520492 | G10: =B10 -> California | H10: CA | I10: =SUMIFS('NST-EST2024-HU'!D:D,'NST-EST2024-HU'!A:A,G10) -> 14417494 | J10: =AVERAGE(I10,K10) -> 14742619 | K10: =I10*D10/C10 -> 15067744 | L10: =AVERAGE(K10,M10) -> 15221442 | M10: =K10*E10/D10 -> 15375141 | N10: =AVERAGE(M10,O10) -> 15440055 | O10: =M10*F10/E10 -> 15504969 | P10: CA | Q10: =C10 -> 39538223 | R10: =AVERAGE(Q10,S10) -> 40429839 | S10: =Q10*$D10/$C10 -> 41321454 | T10: =AVERAGE(S10,U10) -> 41742954 | U10: =S10*$E10/$D10 -> 42164453 | V10: =AVERAGE(U10,W10) -> 42342473 | W10: =U10*$F10/$E10 -> 42520492
A11: 8 | B11: Colorado | C11: 5773714 | D11: 6387211.4 | E11: 7050081.3 | F11: 7690558.6 | G11: =B11 -> Colorado | H11: CO | I11: =SUMIFS('NST-EST2024-HU'!D:D,'NST-EST2024-HU'!A:A,G11) -> 2500752 | J11: =AVERAGE(I11,K11) -> 2633613.2 | K11: =I11*D11/C11 -> 2766474.4 | L11: =AVERAGE(K11,M11) -> 2910027.8 | M11: =K11*E11/D11 -> 3053581.2 | N11: =AVERAGE(M11,O11) -> 3192285.3 | O11: =M11*F11/E11 -> 3330989.3 | P11: CO | Q11: =C11 -> 5773714 | R11: =AVERAGE(Q11,S11) -> 6080462.7 | S11: =Q11*$D11/$C11 -> 6387211.4 | T11: =AVERAGE(S11,U11) -> 6718646.3 | U11: =S11*$E11/$D11 -> 7050081.3 | V11: =AVERAGE(U11,W11) -> 7370319.9 | W11: =U11*$F11/$E11 -> 7690558.6
A12: 9 | B12: Connecticut | C12: 3605944 | D12: 3629971.1 | E12: 3521129 | F12: 3375527.4 | G12: =B12 -> Connecticut | H12: CT | I12: =SUMIFS('NST-EST2024-HU'!D:D,'NST-EST2024-HU'!A:A,G12) -> 1531476 | J12: =AVERAGE(I12,K12) -> 1536578.3 | K12: =I12*D12/C12 -> 1541680.5 | L12: =AVERAGE(K12,M12) -> 1518567.4 | M12: =K12*E12/D12 -> 1495454.3 | N12: =AVERAGE(M12,O12) -> 1464535.2 | O12: =M12*F12/E12 -> 1433616.1 | P12: CT | Q12: =C12 -> 3605944 | R12: =AVERAGE(Q12,S12) -> 3617957.6 | S12: =Q12*$D12/$C12 -> 3629971.1 | T12: =AVERAGE(S12,U12) -> 3575550.1 | U12: =S12*$E12/$D12 -> 3521129 | V12: =AVERAGE(U12,W12) -> 3448328.2 | W12: =U12*$F12/$E12 -> 3375527.4
A13: 10 | B13: Delaware | C13: 989948 | D13: 1063673 | E13: 1127462.8 | F13: 1181074.4 | G13: =B13 -> Delaware | H13: DE | I13: =SUMIFS('NST-EST2024-HU'!D:D,'NST-EST2024-HU'!A:A,G13) -> 450131 | J13: =AVERAGE(I13,K13) -> 466892.43 | K13: =I13*D13/C13 -> 483653.87 | L13: =AVERAGE(K13,M13) -> 498156.54 | M13: =K13*E13/D13 -> 512659.2 | N13: =AVERAGE(M13,O13) -> 524847.84 | O13: =M13*F13/E13 -> 537036.47 | P13: DE | Q13: =C13 -> 989948 | R13: =AVERAGE(Q13,S13) -> 1026810.5 | S13: =Q13*$D13/$C13 -> 1063673 | T13: =AVERAGE(S13,U13) -> 1095567.9 | U13: =S13*$E13/$D13 -> 1127462.8 | V13: =AVERAGE(U13,W13) -> 1154268.6 | W13: =U13*$F13/$E13 -> 1181074.4
A14: 11 | B14: District of Columbia | C14: 689545 | D14: 761820.35 | E14: 839353.09 | F14: 913940.14 | G14: =B14 -> District of Columbia | H14: DC | I14: =SUMIFS('NST-EST2024-HU'!D:D,'NST-EST2024-HU'!A:A,G14) -> 351429 | J14: =AVERAGE(I14,K14) -> 369846.69 | K14: =I14*D14/C14 -> 388264.38 | L14: =AVERAGE(K14,M14) -> 408021.8 | M14: =K14*E14/D14 -> 427779.21 | N14: =AVERAGE(M14,O14) -> 446785.99 | O14: =M14*F14/E14 -> 465792.76 | P14: DC | Q14: =C14 -> 689545 | R14: =AVERAGE(Q14,S14) -> 725682.67 | S14: =Q14*$D14/$C14 -> 761820.35 | T14: =AVERAGE(S14,U14) -> 800586.72 | U14: =S14*$E14/$D14 -> 839353.09 | V14: =AVERAGE(U14,W14) -> 876646.62 | W14: =U14*$F14/$E14 -> 913940.14
A15: 12 | B15: Florida | C15: 21538187 | D15: 23790046 | E15: 26202483 | F15: 28521380 | G15: =B15 -> Florida | H15: FL | I15: =SUMIFS('NST-EST2024-HU'!D:D,'NST-EST2024-HU'!A:A,G15) -> 9900384 | J15: =AVERAGE(I15,K15) -> 10417936 | K15: =I15*D15/C15 -> 10935488 | L15: =AVERAGE(K15,M15) -> 11489947 | M15: =K15*E15/D15 -> 12044405 | N15: =AVERAGE(M15,O15) -> 12577364 | O15: =M15*F15/E15 -> 13110324 | P15: FL | Q15: =C15 -> 21538187 | R15: =AVERAGE(Q15,S15) -> 22664117 | S15: =Q15*$D15/$C15 -> 23790046 | T15: =AVERAGE(S15,U15) -> 24996264 | U15: =S15*$E15/$D15 -> 26202483 | V15: =AVERAGE(U15,W15) -> 27361931 | W15: =U15*$F15/$E15 -> 28521380
A16: 13 | B16: Georgia | C16: 10711908 | D16: 11534245 | E16: 12262064 | F16: 12883056 | G16: =B16 -> Georgia | H16: GA | I16: =SUMIFS('NST-EST2024-HU'!D:D,'NST-EST2024-HU'!A:A,G16) -> 4423066 | J16: =AVERAGE(I16,K16) -> 4592842.1 | K16: =I16*D16/C16 -> 4762618.3 | L16: =AVERAGE(K16,M16) -> 4912880.4 | M16: =K16*E16/D16 -> 5063142.6 | N16: =AVERAGE(M16,O16) -> 5191349.8 | O16: =M16*F16/E16 -> 5319557.1 | P16: GA | Q16: =C16 -> 10711908 | R16: =AVERAGE(Q16,S16) -> 11123077 | S16: =Q16*$D16/$C16 -> 11534245 | T16: =AVERAGE(S16,U16) -> 11898155 | U16: =S16*$E16/$D16 -> 12262064 | V16: =AVERAGE(U16,W16) -> 12572560 | W16: =U16*$F16/$E16 -> 12883056
A17: 15 | B17: Hawaii | C17: 1455271 | D17: 1529813.7 | E17: 1573524.6 | F17: 1599519.1 | G17: =B17 -> Hawaii | H17: HI | I17: =SUMIFS('NST-EST2024-HU'!D:D,'NST-EST2024-HU'!A:A,G17) -> 562001 | J17: =AVERAGE(I17,K17) -> 576394.56 | K17: =I17*D17/C17 -> 590788.12 | L17: =AVERAGE(K17,M17) -> 599228.32 | M17: =K17*E17/D17 -> 607668.52 | N17: =AVERAGE(M17,O17) -> 612687.85 | O17: =M17*F17/E17 -> 617707.18 | P17: HI | Q17: =C17 -> 1455271 | R17: =AVERAGE(Q17,S17) -> 1492542.3 | S17: =Q17*$D17/$C17 -> 1529813.7 | T17: =AVERAGE(S17,U17) -> 1551669.1 | U17: =S17*$E17/$D17 -> 1573524.6 | V17: =AVERAGE(U17,W17) -> 1586521.8 | W17: =U17*$F17/$E17 -> 1599519.1
A18: 16 | B18: Idaho | C18: 1839106 | D18: 2066264.6 | E18: 2330711.7 | F18: 2598197.2 | G18: =B18 -> Idaho | H18: ID | I18: =SUMIFS('NST-EST2024-HU'!D:D,'NST-EST2024-HU'!A:A,G18) -> 756169 | J18: =AVERAGE(I18,K18) -> 802868.4 | K18: =I18*D18/C18 -> 849567.8 | L18: =AVERAGE(K18,M18) -> 903932.99 | M18: =K18*E18/D18 -> 958298.18 | N18: =AVERAGE(M18,O18) -> 1013288 | O18: =M18*F18/E18 -> 1068277.8 | P18: ID | Q18: =C18 -> 1839106 | R18: =AVERAGE(Q18,S18) -> 1952685.3 | S18: =Q18*$D18/$C18 -> 2066264.6 | T18: =AVERAGE(S18,U18) -> 2198488.1 | U18: =S18*$E18/$D18 -> 2330711.7 | V18: =AVERAGE(U18,W18) -> 2464454.4 | W18: =U18*$F18/$E18 -> 2598197.2
... A56: 56 | B56: Wyoming | C56: 576851 | D56: 586924.91 | E56: 577538.97 | F56: 561643.82 | G56: =B56 -> Wyoming | H56: WY | I56: =SUMIFS('NST-EST2024-HU'!D:D,'NST-EST2024-HU'!A:A,G56) -> 272280 | J56: =AVERAGE(I56,K56) -> 274657.5 | K56: =I56*D56/C56 -> 277034.99 | L56: =AVERAGE(K56,M56) -> 274819.86 | M56: =K56*E56/D56 -> 272604.73 | N56: =AVERAGE(M56,O56) -> 268853.39 | O56: =M56*F56/E56 -> 265102.04 | P56: WY | Q56: =C56 -> 576851 | R56: =AVERAGE(Q56,S56) -> 581887.95 | S56: =Q56*$D56/$C56 -> 586924.91 | T56: =AVERAGE(S56,U56) -> 582231.94 | U56: =S56*$E56/$D56 -> 577538.97 | V56: =AVERAGE(U56,W56) -> 569591.39 | W56: =U56*$F56/$E56 -> 561643.82
A57: Subgroups may not sum to total due to rounding | G57: =B57 -> 0
I58: =SUM(I6:I56) -> 140811440 | J58: =SUM(J6:J56) -> 1.4465558e+08 | K58: =SUM(K6:K56) -> 1.4849971e+08 | L58: =SUM(L6:L56) -> 1.5113049e+08 | M58: =SUM(M6:M56) -> 1.5376127e+08 | N58: =SUM(N6:N56) -> 1.5572731e+08 | O58: =SUM(O6:O56) -> 1.5769336e+08

Sheet state calcs
B1: 2021 | C1: 2022 | D1: 2023 | E1: 2024 | F1: 2025 | G1: 2026 | H1: 2027 | I1: 2028 | J1: 2029 | K1: 2030 | L1: 2031 | M1: 2032 | N1: 2033 | O1: 2034 | P1: 2035 | Q1: 2036 | R1: 2037 | S1: 2038 | T1: 2039 | U1: 2040 | V1: 2041 | W1: 2042 | X1: 2043 | Y1: 2044 | Z1: 2045 | AA1: 2046 | AB1: 2047 | AC1: 2048 | AD1: 2049 | AE1: 2050
A2: AL | B2: {=TREND('Total Pop'!$I6:$J6,'Total Pop'!$I$5:$J$5,'state calcs'!B$1)} -> 2301348.8 | C2: {=TREND('Total Pop'!$I6:$J6,'Total Pop'!$I$5:$J$5,'state calcs'!C$1)} -> 2310003.5 | D2: {=TREND('Total Pop'!$I6:$J6,'Total Pop'!$I$5:$J$5,'state calcs'!D$1)} -> 2318658.3 | E2: {=TREND('Total Pop'!$I6:$J6,'Total Pop'!$I$5:$J$5,'state calcs'!E$1)} -> 2327313 | F2: {=TREND('Total Pop'!$J6:$K6,'Total Pop'!$J$5:$K$5,'state calcs'!F$1)} -> 2335967.8 | G2: {=TREND('Total Pop'!$J6:$K6,'Total Pop'!$J$5:$K$5,'state calcs'!G$1)} -> 2344622.5 | H2: {=TREND('Total Pop'!$J6:$K6,'Total Pop'!$J$5:$K$5,'state calcs'!H$1)} -> 2353277.3 | I2: {=TREND('Total Pop'!$J6:$K6,'Total Pop'!$J$5:$K$5,'state calcs'!I$1)} -> 2361932.1 | J2: {=TREND('Total Pop'!$J6:$K6,'Total Pop'!$J$5:$K$5,'state calcs'!J$1)} -> 2370586.8 | K2: {=TREND('Total Pop'!$K6:$L6,'Total Pop'!$K$5:$L$5,'state calcs'!K$1)} -> 2379241.6 | L2: {=TREND('Total Pop'!$K6:$L6,'Total Pop'!$K$5:$L$5,'state calcs'!L$1)} -> 2381772.8 | M2: {=TREND('Total Pop'!$K6:$L6,'Total Pop'!$K$5:$L$5,'state calcs'!M$1)} -> 2384304 | N2: {=TREND('Total Pop'!$K6:$L6,'Total Pop'!$K$5:$L$5,'state calcs'!N$1)} -> 2386835.2 | O2: {=TREND('Total Pop'!$K6:$L6,'Total Pop'!$K$5:$L$5,'state calcs'!O$1)} -> 2389366.5 | P2: {=TREND('Total Pop'!$L6:$M6,'Total Pop'!$L$5:$M$5,'state calcs'!P$1)} -> 2391897.7 | Q2: {=TREND('Total Pop'!$L6:$M6,'Total Pop'!$L$5:$M$5,'state calcs'!Q$1)} -> 2394428.9 | R2: {=TREND('Total Pop'!$L6:$M6,'Total Pop'!$L$5:$M$5,'state calcs'!R$1)} -> 2396960.1 | S2: {=TREND('Total Pop'!$L6:$M6,'Total Pop'!$L$5:$M$5,'state calcs'!S$1)} -> 2399491.4 | T2: {=TREND('Total Pop'!$L6:$M6,'Total Pop'!$L$5:$M$5,'state calcs'!T$1)} -> 2402022.6 | U2: {=TREND('Total Pop'!$M6:$N6,'Total Pop'!$M$5:$N$5,'state calcs'!U$1)} -> 2404553.8 | V2: {=TREND('Total Pop'!$M6:$N6,'Total Pop'!$M$5:$N$5,'state calcs'!V$1)} -> 2404264.4 | W2: {=TREND('Total Pop'!$M6:$N6,'Total Pop'!$M$5:$N$5,'state calcs'!W$1)} -> 2403974.9 | X2: {=TREND('Total Pop'!$M6:$N6,'Total Pop'!$M$5:$N$5,'state calcs'!X$1)} -> 2403685.5 | Y2: {=TREND('Total Pop'!$M6:$N6,'Total Pop'!$M$5:$N$5,'state calcs'!Y$1)} -> 2403396 | Z2: {=TREND('Total Pop'!$N6:$O6,'Total Pop'!$N$5:$O$5,'state calcs'!Z$1)} -> 2403106.6 | AA2: {=TREND('Total Pop'!$N6:$O6,'Total Pop'!$N$5:$O$5,'state calcs'!AA$1)} -> 2402817.1 | AB2: {=TREND('Total Pop'!$N6:$O6,'Total Pop'!$N$5:$O$5,'state calcs'!AB$1)} -> 2402527.6 | AC2: {=TREND('Total Pop'!$N6:$O6,'Total Pop'!$N$5:$O$5,'state calcs'!AC$1)} -> 2402238.2 | AD2: {=TREND('Total Pop'!$N6:$O6,'Total Pop'!$N$5:$O$5,'state calcs'!AD$1)} -> 2401948.7 | AE2: {=TREND('Total Pop'!$N6:$O6,'Total Pop'!$N$5:$O$5,'state calcs'!AE$1)} -> 2401659.3
A3: AK | B3: {=TREND('Total Pop'!$I7:$J7,'Total Pop'!$I$5:$J$5,'state calcs'!B$1)} -> 327383.34 | C3: {=TREND('Total Pop'!$I7:$J7,'Total Pop'!$I$5:$J$5,'state calcs'!C$1)} -> 328173.67 | D3: {=TREND('Total Pop'!$I7:$J7,'Total Pop'!$I$5:$J$5,'state calcs'!D$1)} -> 328964.01 | E3: {=TREND('Total Pop'!$I7:$J7,'Total Pop'!$I$5:$J$5,'state calcs'!E$1)} -> 329754.34 | F3: {=TREND('Total Pop'!$J7:$K7,'Total Pop'!$J$5:$K$5,'state calcs'!F$1)} -> 330544.68 | G3: {=TREND('Total Pop'!$J7:$K7,'Total Pop'!$J$5:$K$5,'state calcs'!G$1)} -> 331335.01 | H3: {=TREND('Total Pop'!$J7:$K7,'Total Pop'!$J$5:$K$5,'state calcs'!H$1)} -> 332125.35 | I3: {=TREND('Total Pop'!$J7:$K7,'Total Pop'!$J$5:$K$5,'state calcs'!I$1)} -> 332915.68 | J3: {=TREND('Total Pop'!$J7:$K7,'Total Pop'!$J$5:$K$5,'state calcs'!J$1)} -> 333706.02 | K3: {=TREND('Total Pop'!$K7:$L7,'Total Pop'!$K$5:$L$5,'state calcs'!K$1)} -> 334496.35 | L3: {=TREND('Total Pop'!$K7:$L7,'Total Pop'!$K$5:$L$5,'state calcs'!L$1)} -> 334255.54 | M3: {=TREND('Total Pop'!$K7:$L7,'Total Pop'!$K$5:$L$5,'state calcs'!M$1)} -> 334014.72 | N3: {=TREND('Total Pop'!$K7:$L7,'Total Pop'!$K$5:$L$5,'state calcs'!N$1)} -> 333773.91 | O3: {=TREND('Total Pop'!$K7:$L7,'Total Pop'!$K$5:$L$5,'state calcs'!O$1)} -> 333533.1 | P3: {=TREND('Total Pop'!$L7:$M7,'Total Pop'!$L$5:$M$5,'state calcs'!P$1)} -> 333292.28 | Q3: {=TREND('Total Pop'!$L7:$M7,'Total Pop'!$L$5:$M$5,'state calcs'!Q$1)} -> 333051.47 | R3: {=TREND('Total Pop'!$L7:$M7,'Total Pop'!$L$5:$M$5,'state calcs'!R$1)} -> 332810.65 | S3: {=TREND('Total Pop'!$L7:$M7,'Total Pop'!$L$5:$M$5,'state calcs'!S$1)} -> 332569.84 | T3: {=TREND('Total Pop'!$L7:$M7,'Total Pop'!$L$5:$M$5,'state calcs'!T$1)} -> 332329.03 | U3: {=TREND('Total Pop'!$M7:$N7,'Total Pop'!$M$5:$N$5,'state calcs'!U$1)} -> 332088.21 | V3: {=TREND('Total Pop'!$M7:$N7,'Total Pop'!$M$5:$N$5,'state calcs'!V$1)} -> 331462.8 | W3: {=TREND('Total Pop'!$M7:$N7,'Total Pop'!$M$5:$N$5,'state calcs'!W$1)} -> 330837.38 | X3: {=TREND('Total Pop'!$M7:$N7,'Total Pop'!$M$5:$N$5,'state calcs'!X$1)} -> 330211.96 | Y3: {=TREND('Total Pop'!$M7:$N7,'Total Pop'!$M$5:$N$5,'state calcs'!Y$1)} -> 329586.55 | Z3: {=TREND('Total Pop'!$N7:$O7,'Total Pop'!$N$5:$O$5,'state calcs'!Z$1)} -> 328961.13 | AA3: {=TREND('Total Pop'!$N7:$O7,'Total Pop'!$N$5:$O$5,'state calcs'!AA$1)} -> 328335.72 | AB3: {=TREND('Total Pop'!$N7:$O7,'Total Pop'!$N$5:$O$5,'state calcs'!AB$1)} -> 327710.3 | AC3: {=TREND('Total Pop'!$N7:$O7,'Total Pop'!$N$5:$O$5,'state calcs'!AC$1)} -> 327084.88 | AD3: {=TREND('Total Pop'!$N7:$O7,'Total Pop'!$N$5:$O$5,'state calcs'!AD$1)} -> 326459.47 | AE3: {=TREND('Total Pop'!$N7:$O7,'Total Pop'!$N$5:$O$5,'state calcs'!AE$1)} -> 325834.05
A4: AZ | B4: {=TREND('Total Pop'!$I8:$J8,'Total Pop'!$I$5:$J$5,'state calcs'!B$1)} -> 3119513.4 | C4: {=TREND('Total Pop'!$I8:$J8,'Total Pop'!$I$5:$J$5,'state calcs'!C$1)} -> 3146099.8 | D4: {=TREND('Total Pop'!$I8:$J8,'Total Pop'!$I$5:$J$5,'state calcs'!D$1)} -> 3172686.2 | E4: {=TREND('Total Pop'!$I8:$J8,'Total Pop'!$I$5:$J$5,'state calcs'!E$1)} -> 3199272.6 | F4: {=TREND('Total Pop'!$J8:$K8,'Total Pop'!$J$5:$K$5,'state calcs'!F$1)} -> 3225859 | G4: {=TREND('Total Pop'!$J8:$K8,'Total Pop'!$J$5:$K$5,'state calcs'!G$1)} -> 3252445.4 | H4: {=TREND('Total Pop'!$J8:$K8,'Total Pop'!$J$5:$K$5,'state calcs'!H$1)} -> 3279031.8 | I4: {=TREND('Total Pop'!$J8:$K8,'Total Pop'!$J$5:$K$5,'state calcs'!I$1)} -> 3305618.2 | J4: {=TREND('Total Pop'!$J8:$K8,'Total Pop'!$J$5:$K$5,'state calcs'!J$1)} -> 3332204.6 | K4: {=TREND('Total Pop'!$K8:$L8,'Total Pop'!$K$5:$L$5,'state calcs'!K$1)} -> 3358791 | L4: {=TREND('Total Pop'!$K8:$L8,'Total Pop'!$K$5:$L$5,'state calcs'!L$1)} -> 3384212.3 | M4: {=TREND('Total Pop'!$K8:$L8,'Total Pop'!$K$5:$L$5,'state calcs'!M$1)} -> 3409633.6 | N4: {=TREND('Total Pop'!$K8:$L8,'Total Pop'!$K$5:$L$5,'state calcs'!N$1)} -> 3435054.9 | O4: {=TREND('Total Pop'!$K8:$L8,'Total Pop'!$K$5:$L$5,'state calcs'!O$1)} -> 3460476.2 | P4: {=TREND('Total Pop'!$L8:$M8,'Total Pop'!$L$5:$M$5,'state calcs'!P$1)} -> 3485897.5 | Q4: {=TREND('Total Pop'!$L8:$M8,'Total Pop'!$L$5:$M$5,'state calcs'!Q$1)} -> 3511318.9 | R4: {=TREND('Total Pop'!$L8:$M8,'Total Pop'!$L$5:$M$5,'state calcs'!R$1)} -> 3536740.2 | S4: {=TREND('Total Pop'!$L8:$M8,'Total Pop'!$L$5:$M$5,'state calcs'!S$1)} -> 3562161.5 | T4: {=TREND('Total Pop'!$L8:$M8,'Total Pop'!$L$5:$M$5,'state calcs'!T$1)} -> 3587582.8 | U4: {=TREND('Total Pop'!$M8:$N8,'Total Pop'!$M$5:$N$5,'state calcs'!U$1)} -> 3613004.1 | V4: {=TREND('Total Pop'!$M8:$N8,'Total Pop'!$M$5:$N$5,'state calcs'!V$1)} -> 3635795.3 | W4: {=TREND('Total Pop'!$M8:$N8,'Total Pop'!$M$5:$N$5,'state calcs'!W$1)} -> 3658586.5 | X4: {=TREND('Total Pop'!$M8:$N8,'Total Pop'!$M$5:$N$5,'state calcs'!X$1)} -> 3681377.8 | Y4: {=TREND('Total Pop'!$M8:$N8,'Total Pop'!$M$5:$N$5,'state calcs'!Y$1)} -> 3704169 | Z4: {=TREND('Total Pop'!$N8:$O8,'Total Pop'!$N$5:$O$5,'state calcs'!Z$1)} -> 3726960.2 | AA4: {=TREND('Total Pop'!$N8:$O8,'Total Pop'!$N$5:$O$5,'state calcs'!AA$1)} -> 3749751.4 | AB4: {=TREND('Total Pop'!$N8:$O8,'Total Pop'!$N$5:$O$5,'state calcs'!AB$1)} -> 3772542.7 | AC4: {=TREND('Total Pop'!$N8:$O8,'Total Pop'!$N$5:$O$5,'state calcs'!AC$1)} -> 3795333.9 | AD4: {=TREND('Total Pop'!$N8:$O8,'Total Pop'!$N$5:$O$5,'state calcs'!AD$1)} -> 3818125.1 | AE4: {=TREND('Total Pop'!$N8:$O8,'Total Pop'!$N$5:$O$5,'state calcs'!AE$1)} -> 3840916.4
A5: AR | B5: {=TREND('Total Pop'!$I9:$J9,'Total Pop'!$I$5:$J$5,'state calcs'!B$1)} -> 1371542.9 | C5: {=TREND('Total Pop'!$I9:$J9,'Total Pop'!$I$5:$J$5,'state calcs'!C$1)} -> 1374871.9 | D5: {=TREND('Total Pop'!$I9:$J9,'Total Pop'!$I$5:$J$5,'state calcs'!D$1)} -> 1378200.8 | E5: {=TREND('Total Pop'!$I9:$J9,'Total Pop'!$I$5:$J$5,'state calcs'!E$1)} -> 1381529.7 | F5: {=TREND('Total Pop'!$J9:$K9,'Total Pop'!$J$5:$K$5,'state calcs'!F$1)} -> 1384858.7 | G5: {=TREND('Total Pop'!$J9:$K9,'Total Pop'!$J$5:$K$5,'state calcs'!G$1)} -> 1388187.6 | H5: {=TREND('Total Pop'!$J9:$K9,'Total Pop'!$J$5:$K$5,'state calcs'!H$1)} -> 1391516.5 | I5: {=TREND('Total Pop'!$J9:$K9,'Total Pop'!$J$5:$K$5,'state calcs'!I$1)} -> 1394845.5 | J5: {=TREND('Total Pop'!$J9:$K9,'Total Pop'!$J$5:$K$5,'state calcs'!J$1)} -> 1398174.4 | K5: {=TREND('Total Pop'!$K9:$L9,'Total Pop'!$K$5:$L$5,'state calcs'!K$1)} -> 1401503.3 | L5: {=TREND('Total Pop'!$K9:$L9,'Total Pop'!$K$5:$L$5,'state calcs'!L$1)} -> 1400518.4 | M5: {=TREND('Total Pop'!$K9:$L9,'Total Pop'!$K$5:$L$5,'state calcs'!M$1)} -> 1399533.5 | N5: {=TREND('Total Pop'!$K9:$L9,'Total Pop'!$K$5:$L$5,'state calcs'!N$1)} -> 1398548.5 | O5: {=TREND('Total Pop'!$K9:$L9,'Total Pop'!$K$5:$L$5,'state calcs'!O$1)} -> 1397563.6 | P5: {=TREND('Total Pop'!$L9:$M9,'Total Pop'!$L$5:$M$5,'state calcs'!P$1)} -> 1396578.7 | Q5: {=TREND('Total Pop'!$L9:$M9,'Total Pop'!$L$5:$M$5,'state calcs'!Q$1)} -> 1395593.7 | R5: {=TREND('Total Pop'!$L9:$M9,'Total Pop'!$L$5:$M$5,'state calcs'!R$1)} -> 1394608.8 | S5: {=TREND('Total Pop'!$L9:$M9,'Total Pop'!$L$5:$M$5,'state calcs'!S$1)} -> 1393623.9 | T5: {=TREND('Total Pop'!$L9:$M9,'Total Pop'!$L$5:$M$5,'state calcs'!T$1)} -> 1392638.9 | U5: {=TREND('Total Pop'!$M9:$N9,'Total Pop'!$M$5:$N$5,'state calcs'!U$1)} -> 1391654 | V5: {=TREND('Total Pop'!$M9:$N9,'Total Pop'!$M$5:$N$5,'state calcs'!V$1)} -> 1389056.7 | W5: {=TREND('Total Pop'!$M9:$N9,'Total Pop'!$M$5:$N$5,'state calcs'!W$1)} -> 1386459.5 | X5: {=TREND('Total Pop'!$M9:$N9,'Total Pop'!$M$5:$N$5,'state calcs'!X$1)} -> 1383862.2 | Y5: {=TREND('Total Pop'!$M9:$N9,'Total Pop'!$M$5:$N$5,'state calcs'!Y$1)} -> 1381264.9 | Z5: {=TREND('Total Pop'!$N9:$O9,'Total Pop'!$N$5:$O$5,'state calcs'!Z$1)} -> 1378667.6 | AA5: {=TREND('Total Pop'!$N9:$O9,'Total Pop'!$N$5:$O$5,'state calcs'!AA$1)} -> 1376070.4 | AB5: {=TREND('Total Pop'!$N9:$O9,'Total Pop'!$N$5:$O$5,'state calcs'!AB$1)} -> 1373473.1 | AC5: {=TREND('Total Pop'!$N9:$O9,'Total Pop'!$N$5:$O$5,'state calcs'!AC$1)} -> 1370875.8 | AD5: {=TREND('Total Pop'!$N9:$O9,'Total Pop'!$N$5:$O$5,'state calcs'!AD$1)} -> 1368278.5 | AE5: {=TREND('Total Pop'!$N9:$O9,'Total Pop'!$N$5:$O$5,'state calcs'!AE$1)} -> 1365681.3
A6: CA | B6: {=TREND('Total Pop'!$I10:$J10,'Total Pop'!$I$5:$J$5,'state calcs'!B$1)} -> 14482519 | C6: {=TREND('Total Pop'!$I10:$J10,'Total Pop'!$I$5:$J$5,'state calcs'!C$1)} -> 14547544 | D6: {=TREND('Total Pop'!$I10:$J10,'Total Pop'!$I$5:$J$5,'state calcs'!D$1)} -> 14612569 | E6: {=TREND('Total Pop'!$I10:$J10,'Total Pop'!$I$5:$J$5,'state calcs'!E$1)} -> 14677594 | F6: {=TREND('Total Pop'!$J10:$K10,'Total Pop'!$J$5:$K$5,'state calcs'!F$1)} -> 14742619 | G6: {=TREND('Total Pop'!$J10:$K10,'Total Pop'!$J$5:$K$5,'state calcs'!G$1)} -> 14807644 | H6: {=TREND('Total Pop'!$J10:$K10,'Total Pop'!$J$5:$K$5,'state calcs'!H$1)} -> 14872669 | I6: {=TREND('Total Pop'!$J10:$K10,'Total Pop'!$J$5:$K$5,'state calcs'!I$1)} -> 14937694 | J6: {=TREND('Total Pop'!$J10:$K10,'Total Pop'!$J$5:$K$5,'state calcs'!J$1)} -> 15002719 | K6: {=TREND('Total Pop'!$K10:$L10,'Total Pop'!$K$5:$L$5,'state calcs'!K$1)} -> 15067744 | L6: {=TREND('Total Pop'!$K10:$L10,'Total Pop'!$K$5:$L$5,'state calcs'!L$1)} -> 15098484 | M6: {=TREND('Total Pop'!$K10:$L10,'Total Pop'!$K$5:$L$5,'state calcs'!M$1)} -> 15129223 | N6: {=TREND('Total Pop'!$K10:$L10,'Total Pop'!$K$5:$L$5,'state calcs'!N$1)} -> 15159963 | O6: {=TREND('Total Pop'!$K10:$L10,'Total Pop'!$K$5:$L$5,'state calcs'!O$1)} -> 15190703 | P6: {=TREND('Total Pop'!$L10:$M10,'Total Pop'!$L$5:$M$5,'state calcs'!P$1)} -> 15221442 | Q6: {=TREND('Total Pop'!$L10:$M10,'Total Pop'!$L$5:$M$5,'state calcs'!Q$1)} -> 15252182 | R6: {=TREND('Total Pop'!$L10:$M10,'Total Pop'!$L$5:$M$5,'state calcs'!R$1)} -> 15282922 | S6: {=TREND('Total Pop'!$L10:$M10,'Total Pop'!$L$5:$M$5,'state calcs'!S$1)} -> 15313662 | T6: {=TREND('Total Pop'!$L10:$M10,'Total Pop'!$L$5:$M$5,'state calcs'!T$1)} -> 15344401 | U6: {=TREND('Total Pop'!$M10:$N10,'Total Pop'!$M$5:$N$5,'state calcs'!U$1)} -> 15375141 | V6: {=TREND('Total Pop'!$M10:$N10,'Total Pop'!$M$5:$N$5,'state calcs'!V$1)} -> 15388124 | W6: {=TREND('Total Pop'!$M10:$N10,'Total Pop'!$M$5:$N$5,'state calcs'!W$1)} -> 15401107 | X6: {=TREND('Total Pop'!$M10:$N10,'Total Pop'!$M$5:$N$5,'state calcs'!X$1)} -> 15414089 | Y6: {=TREND('Total Pop'!$M10:$N10,'Total Pop'!$M$5:$N$5,'state calcs'!Y$1)} -> 15427072 | Z6: {=TREND('Total Pop'!$N10:$O10,'Total Pop'!$N$5:$O$5,'state calcs'!Z$1)} -> 15440055 | AA6: {=TREND('Total Pop'!$N10:$O10,'Total Pop'!$N$5:$O$5,'state calcs'!AA$1)} -> 15453038 | AB6: {=TREND('Total Pop'!$N10:$O10,'Total Pop'!$N$5:$O$5,'state calcs'!AB$1)} -> 15466021 | AC6: {=TREND('Total Pop'!$N10:$O10,'Total Pop'!$N$5:$O$5,'state calcs'!AC$1)} -> 15479004 | AD6: {=TREND('Total Pop'!$N10:$O10,'Total Pop'!$N$5:$O$5,'state calcs'!AD$1)} -> 15491986 | AE6: {=TREND('Total Pop'!$N10:$O10,'Total Pop'!$N$5:$O$5,'state calcs'!AE$1)} -> 15504969
